Workbook

Sheet 工作表1
A1: 股票代號 | B1: 股票名稱 | C1: 發行股數 | D1: 股價 | E1: 總市值 | F1: 市值排名 | G1: 第 1 欄
A2: 2330 | B2: 台積電 | C2: =IFERROR(__xludf.DUMMYFUNCTION("GOOGLEFINANCE(""TPE:"" & A2, ""marketcap"") / GOOGLEFINANCE(""TPE:"" & A2, ""price"")"),2.593252E10) -> 25932520000 | D2: =IFERROR(__xludf.DUMMYFUNCTION("IF(ISBLANK(A2),,GOOGLEFINANCE(""TPE:""&A2, ""price""))"),1505.0) -> 1505 | E2: =IF(ISBLANK(D2),, (C2 * D2) / 100000000) -> 390284.43 | F2: =RANK(E2, E$2:E$100) -> 1 | G2: =IF(COUNTIF('0050_List'!A:A, A2), "✅", "") -> ✅
A3: 2317 | B3: 鴻海 | C3: =IFERROR(__xludf.DUMMYFUNCTION("GOOGLEFINANCE(""TPE:"" & A3, ""marketcap"") / GOOGLEFINANCE(""TPE:"" & A3, ""price"")"),1.396422E10) -> 13964220000 | D3: =IFERROR(__xludf.DUMMYFUNCTION("IF(ISBLANK(A3),,GOOGLEFINANCE(""TPE:""&A3, ""price""))"),233.5) -> 233.5 | E3: =IF(ISBLANK(D3),, (C3 * D3) / 100000000) -> 32606.454 | F3: =RANK(E3, E$2:E$100) -> 2 | G3: =IF(COUNTIF('0050_List'!A:A, A3), "✅", "") -> ✅
A4: 2308 | B4: 台達電 | C4: =IFERROR(__xludf.DUMMYFUNCTION("GOOGLEFINANCE(""TPE:"" & A4, ""marketcap"") / GOOGLEFINANCE(""TPE:"" & A4, ""price"")"),2.597543E9) -> 2597543000 | D4: =IFERROR(__xludf.DUMMYFUNCTION("IF(ISBLANK(A4),,GOOGLEFINANCE(""TPE:""&A4, ""price""))"),968.0) -> 968 | E4: =IF(ISBLANK(D4),, (C4 * D4) / 100000000) -> 25144.216 | F4: =RANK(E4, E$2:E$100) -> 3 | G4: =IF(COUNTIF('0050_List'!A:A, A4), "✅", "") -> ✅
A5: 2454 | B5: 聯發科 | C5: =IFERROR(__xludf.DUMMYFUNCTION("GOOGLEFINANCE(""TPE:"" & A5, ""marketcap"") / GOOGLEFINANCE(""TPE:"" & A5, ""price"")"),1.603912E9) -> 1603912000 | D5: =IFERROR(__xludf.DUMMYFUNCTION("IF(ISBLANK(A5),,GOOGLEFINANCE(""TPE:""&A5, ""price""))"),1460.0) -> 1460 | E5: =IF(ISBLANK(D5),, (C5 * D5) / 100000000) -> 23417.115 | F5: =RANK(E5, E$2:E$100) -> 4 | G5: =IF(COUNTIF('0050_List'!A:A, A5), "✅", "") -> ✅
A6: 2881 | B6: 富邦金 | C6: =IFERROR(__xludf.DUMMYFUNCTION("GOOGLEFINANCE(""TPE:"" & A6, ""marketcap"") / GOOGLEFINANCE(""TPE:"" & A6, ""price"")"),1.5025579518329832E10) -> 15025579518 | D6: =IFERROR(__xludf.DUMMYFUNCTION("IF(ISBLANK(A6),,GOOGLEFINANCE(""TPE:""&A6, ""price""))"),95.2) -> 95.2 | E6: =IF(ISBLANK(D6),, (C6 * D6) / 100000000) -> 14304.352 | F6: =RANK(E6, E$2:E$100) -> 5 | G6: =IF(COUNTIF('0050_List'!A:A, A6), "✅", "") -> ✅
A7: 2382 | B7: 廣達 | C7: =IFERROR(__xludf.DUMMYFUNCTION("GOOGLEFINANCE(""TPE:"" & A7, ""marketcap"") / GOOGLEFINANCE(""TPE:"" & A7, ""price"")"),3.862628E9) -> 3862628000 | D7: =IFERROR(__xludf.DUMMYFUNCTION("IF(ISBLANK(A7),,GOOGLEFINANCE(""TPE:""&A7, ""price""))"),292.5) -> 292.5 | E7: =IF(ISBLANK(D7),, (C7 * D7) / 100000000) -> 11298.187 | F7: =RANK(E7, E$2:E$100) -> 6 | G7: =IF(COUNTIF('0050_List'!A:A, A7), "✅", "") -> ✅
A8: 2882 | B8: 國泰金 | C8: =IFERROR(__xludf.DUMMYFUNCTION("GOOGLEFINANCE(""TPE:"" & A8, ""marketcap"") / GOOGLEFINANCE(""TPE:"" & A8, ""price"")"),1.601318E10) -> 16013180000 | D8: =IFERROR(__xludf.DUMMYFUNCTION("IF(ISBLANK(A8),,GOOGLEFINANCE(""TPE:""&A8, ""price""))"),68.5) -> 68.5 | E8: =IF(ISBLANK(D8),, (C8 * D8) / 100000000) -> 10969.028 | F8: =RANK(E8, E$2:E$100) -> 7 | G8: =IF(COUNTIF('0050_List'!A:A, A8), "✅", "") -> ✅
A9: 3711 | B9: 日月光投控 | C9: =IFERROR(__xludf.DUMMYFUNCTION("GOOGLEFINANCE(""TPE:"" & A9, ""marketcap"") / GOOGLEFINANCE(""TPE:"" & A9, ""price"")"),4.436143E9) -> 4436143000 | D9: =IFERROR(__xludf.DUMMYFUNCTION("IF(ISBLANK(A9),,GOOGLEFINANCE(""TPE:""&A9, ""price""))"),244.5) -> 244.5 | E9: =IF(ISBLANK(D9),, (C9 * D9) / 100000000) -> 10846.37 | F9: =RANK(E9, E$2:E$100) -> 8 | G9: =IF(COUNTIF('0050_List'!A:A, A9), "✅", "") -> ✅
A10: 2412 | B10: 中華電 | C10: =IFERROR(__xludf.DUMMYFUNCTION("GOOGLEFINANCE(""TPE:"" & A10, ""marketcap"") / GOOGLEFINANCE(""TPE:"" & A10, ""price"")"),7.757444E9) -> 7757444000 | D10: =IFERROR(__xludf.DUMMYFUNCTION("IF(ISBLANK(A10),,GOOGLEFINANCE(""TPE:""&A10, ""price""))"),129.5) -> 129.5 | E10: =IF(ISBLANK(D10),, (C10 * D10) / 100000000) -> 10045.89 | F10: =RANK(E10, E$2:E$100) -> 9 | G10: =IF(COUNTIF('0050_List'!A:A, A10), "✅", "") -> ✅
A11: 2891 | B11: 中信金 | C11: =IFERROR(__xludf.DUMMYFUNCTION("GOOGLEFINANCE(""TPE:"" & A11, ""marketcap"") / GOOGLEFINANCE(""TPE:"" & A11, ""price"")"),2.0352699653392857E10) -> 20352699653 | D11: =IFERROR(__xludf.DUMMYFUNCTION("IF(ISBLANK(A11),,GOOGLEFINANCE(""TPE:""&A11, ""price""))"),44.8) -> 44.8 | E11: =IF(ISBLANK(D11),, (C11 * D11) / 100000000) -> 9118.0094 | F11: =RANK(E11, E$2:E$100) -> 10 | G11: =IF(COUNTIF('0050_List'!A:A, A11), "✅", "") -> ✅
A12: 6669 | B12: 緯穎 | C12: =IFERROR(__xludf.DUMMYFUNCTION("GOOGLEFINANCE(""TPE:"" & A12, ""marketcap"") / GOOGLEFINANCE(""TPE:"" & A12, ""price"")"),1.858407E8) -> 185840700 | D12: =IFERROR(__xludf.DUMMYFUNCTION("IF(ISBLANK(A12),,GOOGLEFINANCE(""TPE:""&A12, ""price""))"),4525.0) -> 4525 | E12: =IF(ISBLANK(D12),, (C12 * D12) / 100000000) -> 8409.2917 | F12: =RANK(E12, E$2:E$100) -> 11 | G12: =IF(COUNTIF('0050_List'!A:A, A12), "✅", "") -> ✅
A13: 2303 | B13: 聯電 | C13: =IFERROR(__xludf.DUMMYFUNCTION("GOOGLEFINANCE(""TPE:"" & A13, ""marketcap"") / GOOGLEFINANCE(""TPE:"" & A13, ""price"")"),1.2555269611793312E10) -> 12555269612 | D13: =IFERROR(__xludf.DUMMYFUNCTION("IF(ISBLANK(A13),,GOOGLEFINANCE(""TPE:""&A13, ""price""))"),49.35) -> 49.35 | E13: =IF(ISBLANK(D13),, (C13 * D13) / 100000000) -> 6196.0256 | F13: =RANK(E13, E$2:E$100) -> 12 | G13: =IF(COUNTIF('0050_List'!A:A, A13), "✅", "") -> ✅
A14: 2886 | B14: 兆豐金 | C14: =IFERROR(__xludf.DUMMYFUNCTION("GOOGLEFINANCE(""TPE:"" & A14, ""marketcap"") / GOOGLEFINANCE(""TPE:"" & A14, ""price"")"),1.4833370556777369E10) -> 14833370557 | D14: =IFERROR(__xludf.DUMMYFUNCTION("IF(ISBLANK(A14),,GOOGLEFINANCE(""TPE:""&A14, ""price""))"),40.65) -> 40.65 | E14: =IF(ISBLANK(D14),, (C14 * D14) / 100000000) -> 6029.7651 | F14: =RANK(E14, E$2:E$100) -> 14 | G14: =IF(COUNTIF('0050_List'!A:A, A14), "✅", "") -> ✅
A15: 2887 | B15: 台新新光金 | C15: =IFERROR(__xludf.DUMMYFUNCTION("GOOGLEFINANCE(""TPE:"" & A15, ""marketcap"") / GOOGLEFINANCE(""TPE:"" & A15, ""price"")"),2.926269941707572E10) -> 29262699417 | D15: =IFERROR(__xludf.DUMMYFUNCTION("IF(ISBLANK(A15),,GOOGLEFINANCE(""TPE:""&A15, ""price""))"),19.15) -> 19.15 | E15: =IF(ISBLANK(D15),, (C15 * D15) / 100000000) -> 5603.8069 | F15: =RANK(E15, E$2:E$100) -> 16 | G15: =IF(COUNTIF('0050_List'!A:A, A15), "✅", "") -> ✅
A16: 2345 | B16: 智邦 | C16: =IFERROR(__xludf.DUMMYFUNCTION("GOOGLEFINANCE(""TPE:"" & A16, ""marketcap"") / GOOGLEFINANCE(""TPE:"" & A16, ""price"")"),5.611179E8) -> 561117900 | D16: =IFERROR(__xludf.DUMMYFUNCTION("IF(ISBLANK(A16),,GOOGLEFINANCE(""TPE:""&A16, ""price""))"),1090.0) -> 1090 | E16: =IF(ISBLANK(D16),, (C16 * D16) / 100000000) -> 6116.1851 | F16: =RANK(E16, E$2:E$100) -> 13 | G16: =IF(COUNTIF('0050_List'!A:A, A16), "✅", "") -> ✅
A17: 3017 | B17: 奇鋐 | C17: =IFERROR(__xludf.DUMMYFUNCTION("GOOGLEFINANCE(""TPE:"" & A17, ""marketcap"") / GOOGLEFINANCE(""TPE:"" & A17, ""price"")"),3.881796E8) -> 388179600 | D17: =IFERROR(__xludf.DUMMYFUNCTION("IF(ISBLANK(A17),,GOOGLEFINANCE(""TPE:""&A17, ""price""))"),1425.0) -> 1425 | E17: =IF(ISBLANK(D17),, (C17 * D17) / 100000000) -> 5531.5593 | F17: =RANK(E17, E$2:E$100) -> 17 | G17: =IF(COUNTIF('0050_List'!A:A, A17), "✅", "") -> ✅
A18: 2383 | B18: 台光電 | C18: =IFERROR(__xludf.DUMMYFUNCTION("GOOGLEFINANCE(""TPE:"" & A18, ""marketcap"") / GOOGLEFINANCE(""TPE:"" & A18, ""price"")"),3.575354E8) -> 357535400 | D18: =IFERROR(__xludf.DUMMYFUNCTION("IF(ISBLANK(A18),,GOOGLEFINANCE(""TPE:""&A18, ""price""))"),1600.0) -> 1600 | E18: =IF(ISBLANK(D18),, (C18 * D18) / 100000000) -> 5720.5664 | F18: =RANK(E18, E$2:E$100) -> 15 | G18: =IF(COUNTIF('0050_List'!A:A, A18), "✅", "") -> ✅
A19: 2884 | B19: 玉山金 | C19: =IFERROR(__xludf.DUMMYFUNCTION("GOOGLEFINANCE(""TPE:"" & A19, ""marketcap"") / GOOGLEFINANCE(""TPE:"" & A19, ""price"")"),1.6173999231152647E10) -> 16173999231 | D19: =IFERROR(__xludf.DUMMYFUNCTION("IF(ISBLANK(A19),,GOOGLEFINANCE(""TPE:""&A19, ""price""))"),32.1) -> 32.1 | E19: =IF(ISBLANK(D19),, (C19 * D19) / 100000000) -> 5191.8538 | F19: =RANK(E19, E$2:E$100) -> 18 | G19: =IF(COUNTIF('0050_List'!A:A, A19), "✅", "") -> ✅
A20: 2408 | B20: 南亞科 | C20: =IFERROR(__xludf.DUMMYFUNCTION("GOOGLEFINANCE(""TPE:"" & A20, ""marketcap"") / GOOGLEFINANCE(""TPE:"" & A20, ""price"")"),3.098628E9) -> 3098628000 | D20: =IFERROR(__xludf.DUMMYFUNCTION("IF(ISBLANK(A20),,GOOGLEFINANCE(""TPE:""&A20, ""price""))"),156.0) -> 156 | E20: =IF(ISBLANK(D20),, (C20 * D20) / 100000000) -> 4833.8597 | F20: =RANK(E20, E$2:E$100) -> 22 | G20: =IF(COUNTIF('0050_List'!A:A, A20), "✅", "")
A21: 1303 | B21: 南亞 | C21: =IFERROR(__xludf.DUMMYFUNCTION("GOOGLEFINANCE(""TPE:"" & A21, ""marketcap"") / GOOGLEFINANCE(""TPE:"" & A21, ""price"")"),7.930821197084691E9) -> 7930821197 | D21: =IFERROR(__xludf.DUMMYFUNCTION("IF(ISBLANK(A21),,GOOGLEFINANCE(""TPE:""&A21, ""price""))"),61.4) -> 61.4 | E21: =IF(ISBLANK(D21),, (C21 * D21) / 100000000) -> 4869.5242 | F21: =RANK(E21, E$2:E$100) -> 21 | G21: =IF(COUNTIF('0050_List'!A:A, A21), "✅", "") -> ✅
A22: 2885 | B22: 元大金 | C22: =IFERROR(__xludf.DUMMYFUNCTION("GOOGLEFINANCE(""TPE:"" & A22, ""marketcap"") / GOOGLEFINANCE(""TPE:"" & A22, ""price"")"),1.3331140543877007E10) -> 13331140544 | D22: =IFERROR(__xludf.DUMMYFUNCTION("IF(ISBLANK(A22),,GOOGLEFINANCE(""TPE:""&A22, ""price""))"),37.4) -> 37.4 | E22: =IF(ISBLANK(D22),, (C22 * D22) / 100000000) -> 4985.8466 | F22: =RANK(E22, E$2:E$100) -> 20 | G22: =IF(COUNTIF('0050_List'!A:A, A22), "✅", "") -> ✅
A23: 2327 | B23: 國巨* | C23: =IFERROR(__xludf.DUMMYFUNCTION("GOOGLEFINANCE(""TPE:"" & A23, ""marketcap"") / GOOGLEFINANCE(""TPE:"" & A23, ""price"")"),2.072965E9) -> 2072965000 | D23: =IFERROR(__xludf.DUMMYFUNCTION("IF(ISBLANK(A23),,GOOGLEFINANCE(""TPE:""&A23, ""price""))"),245.5) -> 245.5 | E23: =IF(ISBLANK(D23),, (C23 * D23) / 100000000) -> 5089.1291 | F23: =RANK(E23, E$2:E$100) -> 19 | G23: =IF(COUNTIF('0050_List'!A:A, A23), "✅", "") -> ✅
A24: 6505 | B24: 台塑化 | C24: =IFERROR(__xludf.DUMMYFUNCTION("GOOGLEFINANCE(""TPE:"" & A24, ""marketcap"") / GOOGLEFINANCE(""TPE:"" & A24, ""price"")"),9.525958708405216E9) -> 9525958708 | D24: =IFERROR(__xludf.DUMMYFUNCTION("IF(ISBLANK(A24),,GOOGLEFINANCE(""TPE:""&A24, ""price""))"),49.85) -> 49.85 | E24: =IF(ISBLANK(D24),, (C24 * D24) / 100000000) -> 4748.6904 | F24: =RANK(E24, E$2:E$100) -> 23 | G24: =IF(COUNTIF('0050_List'!A:A, A24), "✅", "") -> ✅
A25: 3231 | B25: 緯創 | C25: =IFERROR(__xludf.DUMMYFUNCTION("GOOGLEFINANCE(""TPE:"" & A25, ""marketcap"") / GOOGLEFINANCE(""TPE:"" & A25, ""price"")"),3.180412E9) -> 3180412000 | D25: =IFERROR(__xludf.DUMMYFUNCTION("IF(ISBLANK(A25),,GOOGLEFINANCE(""TPE:""&A25, ""price""))"),147.5) -> 147.5 | E25: =IF(ISBLANK(D25),, (C25 * D25) / 100000000) -> 4691.1077 | F25: =RANK(E25, E$2:E$100) -> 24 | G25: =IF(COUNTIF('0050_List'!A:A, A25), "✅", "") -> ✅
A26: 2357 | B26: 華碩 | C26: =IFERROR(__xludf.DUMMYFUNCTION("GOOGLEFINANCE(""TPE:"" & A26, ""marketcap"") / GOOGLEFINANCE(""TPE:"" & A26, ""price"")"),7.427602E8) -> 742760200 | D26: =IFERROR(__xludf.DUMMYFUNCTION("IF(ISBLANK(A26),,GOOGLEFINANCE(""TPE:""&A26, ""price""))"),595.0) -> 595 | E26: =IF(ISBLANK(D26),, (C26 * D26) / 100000000) -> 4419.4232 | F26: =RANK(E26, E$2:E$100) -> 25 | G26: =IF(COUNTIF('0050_List'!A:A, A26), "✅", "") -> ✅
A27: 3653 | B27: 健策 | C27: =IFERROR(__xludf.DUMMYFUNCTION("GOOGLEFINANCE(""TPE:"" & A27, ""marketcap"") / GOOGLEFINANCE(""TPE:"" & A27, ""price"")"),1.42922E8) -> 142922000 | D27: =IFERROR(__xludf.DUMMYFUNCTION("IF(ISBLANK(A27),,GOOGLEFINANCE(""TPE:""&A27, ""price""))"),2920.0) -> 2920 | E27: =IF(ISBLANK(D27),, (C27 * D27) / 100000000) -> 4173.3224 | F27: =RANK(E27, E$2:E$100) -> 28 | G27: =IF(COUNTIF('0050_List'!A:A, A27), "✅", "")
A28: 1216 | B28: 統一 | C28: =IFERROR(__xludf.DUMMYFUNCTION("GOOGLEFINANCE(""TPE:"" & A28, ""marketcap"") / GOOGLEFINANCE(""TPE:"" & A28, ""price"")"),5.682015E9) -> 5682015000 | D28: =IFERROR(__xludf.DUMMYFUNCTION("IF(ISBLANK(A28),,GOOGLEFINANCE(""TPE:""&A28, ""price""))"),75.0) -> 75 | E28: =IF(ISBLANK(D28),, (C28 * D28) / 100000000) -> 4261.5112 | F28: =RANK(E28, E$2:E$100) -> 26 | G28: =IF(COUNTIF('0050_List'!A:A, A28), "✅", "") -> ✅
A29: 2880 | B29: 華南金 | C29: =IFERROR(__xludf.DUMMYFUNCTION("GOOGLEFINANCE(""TPE:"" & A29, ""marketcap"") / GOOGLEFINANCE(""TPE:"" & A29, ""price"")"),1.3916959652438625E10) -> 13916959652 | D29: =IFERROR(__xludf.DUMMYFUNCTION("IF(ISBLANK(A29),,GOOGLEFINANCE(""TPE:""&A29, ""price""))"),30.55) -> 30.55 | E29: =IF(ISBLANK(D29),, (C29 * D29) / 100000000) -> 4251.6312 | F29: =RANK(E29, E$2:E$100) -> 27 | G29: =IF(COUNTIF('0050_List'!A:A, A29), "✅", "") -> ✅
A30: 2892 | B30: 第一金 | C30: =IFERROR(__xludf.DUMMYFUNCTION("GOOGLEFINANCE(""TPE:"" & A30, ""marketcap"") / GOOGLEFINANCE(""TPE:"" & A30, ""price"")"),1.4379460392486584E10) -> 14379460392 | D30: =IFERROR(__xludf.DUMMYFUNCTION("IF(ISBLANK(A30),,GOOGLEFINANCE(""TPE:""&A30, ""price""))"),27.95) -> 27.95 | E30: =IF(ISBLANK(D30),, (C30 * D30) / 100000000) -> 4019.0592 | F30: =RANK(E30, E$2:E$100) -> 29 | G30: =IF(COUNTIF('0050_List'!A:A, A30), "✅", "") -> ✅
A31: 2890 | B31: 永豐金 | C31: =IFERROR(__xludf.DUMMYFUNCTION("GOOGLEFINANCE(""TPE:"" & A31, ""marketcap"") / GOOGLEFINANCE(""TPE:"" & A31, ""price"")"),1.4492320402768671E10) -> 14492320403 | D31: =IFERROR(__xludf.DUMMYFUNCTION("IF(ISBLANK(A31),,GOOGLEFINANCE(""TPE:""&A31, ""price""))"),27.45) -> 27.45 | E31: =IF(ISBLANK(D31),, (C31 * D31) / 100000000) -> 3978.142 | F31: =RANK(E31, E$2:E$100) -> 30 | G31: =IF(COUNTIF('0050_List'!A:A, A31), "✅", "") -> ✅
A32: 3045 | B32: 台灣大 | C32: =IFERROR(__xludf.DUMMYFUNCTION("GOOGLEFINANCE(""TPE:"" & A32, ""marketcap"") / GOOGLEFINANCE(""TPE:"" & A32, ""price"")"),3.723261E9) -> 3723261000 | D32: =IFERROR(__xludf.DUMMYFUNCTION("IF(ISBLANK(A32),,GOOGLEFINANCE(""TPE:""&A32, ""price""))"),104.5) -> 104.5 | E32: =IF(ISBLANK(D32),, (C32 * D32) / 100000000) -> 3890.8077 | F32: =RANK(E32, E$2:E$100) -> 31 | G32: =IF(COUNTIF('0050_List'!A:A, A32), "✅", "") -> ✅
A33: 2603 | B33: 長榮 | C33: =IFERROR(__xludf.DUMMYFUNCTION("GOOGLEFINANCE(""TPE:"" & A33, ""marketcap"") / GOOGLEFINANCE(""TPE:"" & A33, ""price"")"),2.165043E9) -> 2165043000 | D33: =IFERROR(__xludf.DUMMYFUNCTION("IF(ISBLANK(A33),,GOOGLEFINANCE(""TPE:""&A33, ""price""))"),179.0) -> 179 | E33: =IF(ISBLANK(D33),, (C33 * D33) / 100000000) -> 3875.427 | F33: =RANK(E33, E$2:E$100) -> 32 | G33: =IF(COUNTIF('0050_List'!A:A, A33), "✅", "") -> ✅
A34: 5880 | B34: 合庫金 | C34: =IFERROR(__xludf.DUMMYFUNCTION("GOOGLEFINANCE(""TPE:"" & A34, ""marketcap"") / GOOGLEFINANCE(""TPE:"" & A34, ""price"")"),1.5680930494338844E10) -> 15680930494 | D34: =IFERROR(__xludf.DUMMYFUNCTION("IF(ISBLANK(A34),,GOOGLEFINANCE(""TPE:""&A34, ""price""))"),24.2) -> 24.2 | E34: =IF(ISBLANK(D34),, (C34 * D34) / 100000000) -> 3794.7852 | F34: =RANK(E34, E$2:E$100) -> 33 | G34: =IF(COUNTIF('0050_List'!A:A, A34), "✅", "") -> ✅
A35: 2301 | B35: 光寶科 | C35: =IFERROR(__xludf.DUMMYFUNCTION("GOOGLEFINANCE(""TPE:"" & A35, ""marketcap"") / GOOGLEFINANCE(""TPE:"" & A35, ""price"")"),2.316775E9) -> 2316775000 | D35: =IFERROR(__xludf.DUMMYFUNCTION("IF(ISBLANK(A35),,GOOGLEFINANCE(""TPE:""&A35, ""price""))"),159.5) -> 159.5 | E35: =IF(ISBLANK(D35),, (C35 * D35) / 100000000) -> 3695.2561 | F35: =RANK(E35, E$2:E$100) -> 34 | G35: =IF(COUNTIF('0050_List'!A:A, A35), "✅", "") -> ✅
A36: 3037 | B36: 欣興 | C36: =IFERROR(__xludf.DUMMYFUNCTION("GOOGLEFINANCE(""TPE:"" & A36, ""marketcap"") / GOOGLEFINANCE(""TPE:"" & A36, ""price"")"),1.5756E9) -> 1575600000 | D36: =IFERROR(__xludf.DUMMYFUNCTION("IF(ISBLANK(A36),,GOOGLEFINANCE(""TPE:""&A36, ""price""))"),227.5) -> 227.5 | E36: =IF(ISBLANK(D36),, (C36 * D36) / 100000000) -> 3584.49 | F36: =RANK(E36, E$2:E$100) -> 35 | G36: =IF(COUNTIF('0050_List'!A:A, A36), "✅", "")
A37: 2360 | B37: 致茂 | C37: =IFERROR(__xludf.DUMMYFUNCTION("GOOGLEFINANCE(""TPE:"" & A37, ""marketcap"") / GOOGLEFINANCE(""TPE:"" & A37, ""price"")"),4.252737E8) -> 425273700 | D37: =IFERROR(__xludf.DUMMYFUNCTION("IF(ISBLANK(A37),,GOOGLEFINANCE(""TPE:""&A37, ""price""))"),800.0) -> 800 | E37: =IF(ISBLANK(D37),, (C37 * D37) / 100000000) -> 3402.1896 | F37: =RANK(E37, E$2:E$100) -> 37 | G37: =IF(COUNTIF('0050_List'!A:A, A37), "✅", "")
A38: 2059 | B38: 川湖 | C38: =IFERROR(__xludf.DUMMYFUNCTION("GOOGLEFINANCE(""TPE:"" & A38, ""marketcap"") / GOOGLEFINANCE(""TPE:"" & A38, ""price"")"),9.529708E7) -> 95297080 | D38: =IFERROR(__xludf.DUMMYFUNCTION("IF(ISBLANK(A38),,GOOGLEFINANCE(""TPE:""&A38, ""price""))"),3615.0) -> 3615 | E38: =IF(ISBLANK(D38),, (C38 * D38) / 100000000) -> 3444.9894 | F38: =RANK(E38, E$2:E$100) -> 36 | G38: =IF(COUNTIF('0050_List'!A:A, A38), "✅", "") -> ✅
A39: 2207 | B39: 和泰車 | C39: =IFERROR(__xludf.DUMMYFUNCTION("GOOGLEFINANCE(""TPE:"" & A39, ""marketcap"") / GOOGLEFINANCE(""TPE:"" & A39, ""price"")"),5.571026E8) -> 557102600 | D39: =IFERROR(__xludf.DUMMYFUNCTION("IF(ISBLANK(A39),,GOOGLEFINANCE(""TPE:""&A39, ""price""))"),598.0) -> 598 | E39: =IF(ISBLANK(D39),, (C39 * D39) / 100000000) -> 3331.4735 | F39: =RANK(E39, E$2:E$100) -> 38 | G39: =IF(COUNTIF('0050_List'!A:A, A39), "✅", "") -> ✅
A40: 4904 | B40: 遠傳 | C40: =IFERROR(__xludf.DUMMYFUNCTION("GOOGLEFINANCE(""TPE:"" & A40, ""marketcap"") / GOOGLEFINANCE(""TPE:"" & A40, ""price"")"),3.6057059360975614E9) -> 3605705936 | D40: =IFERROR(__xludf.DUMMYFUNCTION("IF(ISBLANK(A40),,GOOGLEFINANCE(""TPE:""&A40, ""price""))"),86.1) -> 86.1 | E40: =IF(ISBLANK(D40),, (C40 * D40) / 100000000) -> 3104.5128 | F40: =RANK(E40, E$2:E$100) -> 39 | G40: =IF(COUNTIF('0050_List'!A:A, A40), "✅", "") -> ✅
...

Sheet 0050_List
A1: 2330 | B1: 台積電
A2: 2317 | B2: 鴻海
A3: 2454 | B3: 聯發科
A4: 2308 | B4: 台達電
A5: 2382 | B5: 廣達
A6: 2891 | B6: 中信金
A7: 2881 | B7: 富邦金
A8: 2882 | B8: 國泰金
A9: 3711 | B9: 日月光投控
A10: 2303 | B10: 聯電
A11: 2345 | B11: 智邦
A12: 2884 | B12: 玉山金
... A51: 6446 | B51: 藥華藥
